package Exceptions.Assignment

//fun main(args: Array<String>) {
//    test("abcd")
//    println("executes after the validation")
//}
//fun test(password: String) {
//    if (password.length < 6)
//        throw ArithmeticException("Password is too short")
//    else
//        println("Strong password")
//}


//Quiz 2
//fun main(args : Array<String>){
//    try{
//        var ar = arrayOf(1,2,3,4,5)
//        var int = ar[6]
//        println(int)
//    }
//    finally {
//        println("This block always executes")
//    }
//}


//Quiz 3
//fun main (args: Array<String>){
//    try {
//        var int = 10 / 0
//        println(int)
//    } catch (e: ArithmeticException) {
//        println(e)
//    } finally {
//        println("This block always executes")
//    }
//}


//Quiz 4
fun main(args: Array<String>) {
//    try{
//        val a = IntArray(5)
//        a[10] = 99
//    }
//    catch(e: ArithmeticException){
//        println("ArithmeticException occurred")
//    }
//    catch(e: NumberFormatException){
//        println("Number format exception")
//    }
//    catch(e: ArrayIndexOutOfBoundsException){
//        println("Array index is out of range")
//    }
//    catch(e: Exception){
//        println("Some error occurred")
//    }

    println("Out of try catch block")
}
















